{"uuid": "01b017b8-9761-4fd4-a9f7-a2dcd7c36e62", "children": ["dbebfddf-19bb-4306-b5a2-2a5bafc3176b"], "befores": [{"name": "xunit_setup_class_fixture_TestLogin", "status": "broken", "statusDetails": {"message": "selenium.common.exceptions.WebDriverException: Message: An unknown server-side error occurred while processing the command. Original error: Error getting device API level. Original error: Error executing adbExec. Original error: 'Command 'D:\\\\ADB\\\\Android-sdk-windows\\\\platform-tools\\\\adb.exe -P 5037 -s 192.168.0.102\\:8888 shell getprop ro.build.version.sdk' exited with code 1'; Stderr: 'error: device offline'; Code: '1'\n\n", "trace": "  File \"d:\\python37\\lib\\site-packages\\pluggy\\_callers.py\", line 39, in _multicall\n    res = hook_impl.function(*args)\n  File \"d:\\python37\\lib\\site-packages\\_pytest\\fixtures.py\", line 1126, in pytest_fixture_setup\n    result = call_fixture_func(fixturefunc, request, kwargs)\n  File \"d:\\python37\\lib\\site-packages\\_pytest\\fixtures.py\", line 925, in call_fixture_func\n    fixture_result = next(generator)\n  File \"d:\\python37\\lib\\site-packages\\_pytest\\python.py\", line 811, in xunit_setup_class_fixture\n    _call_with_optional_argument(func, self.obj)\n  File \"d:\\python37\\lib\\site-packages\\_pytest\\python.py\", line 739, in _call_with_optional_argument\n    func(arg)\n  File \"E:\\Test_case\\Python\\app_test\\case\\test_login.py\", line 11, in setup_class\n    self.driver = Base.get_driver()\n  File \"E:\\Test_case\\Python\\app_test\\Base\\Driver.py\", line 16, in get_driver\n    return webdriver.Remote(\"http://localhost:4723/wd/hub\", desired_caps)\n  File \"d:\\python37\\lib\\site-packages\\appium\\webdriver\\webdriver.py\", line 157, in __init__\n    AppiumConnection(command_executor, keep_alive=keep_alive), desired_capabilities, browser_profile, proxy\n  File \"d:\\python37\\lib\\site-packages\\selenium\\webdriver\\remote\\webdriver.py\", line 157, in __init__\n    self.start_session(capabilities, browser_profile)\n  File \"d:\\python37\\lib\\site-packages\\appium\\webdriver\\webdriver.py\", line 226, in start_session\n    response = self.execute(RemoteCommand.NEW_SESSION, parameters)\n  File \"d:\\python37\\lib\\site-packages\\selenium\\webdriver\\remote\\webdriver.py\", line 321, in execute\n    self.error_handler.check_response(response)\n  File \"d:\\python37\\lib\\site-packages\\selenium\\webdriver\\remote\\errorhandler.py\", line 242, in check_response\n    raise exception_class(message, screen, stacktrace)\n"}, "start": 1634364985772, "stop": 1634364988713}], "start": 1634364985772, "stop": 1634364988790}